Workbook

Sheet Executive Summary
A1: ASSET AUDIT REPORT - January 2026
A4: Site Code | B4: PLCB | C4: Site Name | D4: KLS
A5: Audit Date | B5: 46028 | C5: Auditor | D5: James Ochard
A6: Audit Period | B6: Q1 2026 | C6: Report Generated | D6: 46058
A9: KEY PERFORMANCE INDICATORS
A10: Site Data | C10: IT Allocation Data | F10: Operational Devices PBI Data
A11: On-Site Total | C11: IT Allocation Total | D11: Variance | F11: PBI Total | G11: Variance | H11: 60-Day Inactive
A12: =I26 -> 397 | C12: =COUNTA('IT Allocation Import'!B3:B441) -> 439 | D12: =A12-C12 -> -42 | F12: ='PBI Import'!A7 -> 367 | G12: =A12-F12 -> 30 | H12: =COUNTIF('PBI Import'!B9:B1048576, "Not Connected in last 60 days") -> 10
A16: ASSET INVENTORY BY TYPE
A17: Device Type | B17: Prior Count | C17: Good | D17: Bad | E17: RMA | F17: Lost | G17: PBI Total | H17: PBI Report Diff | I17: Current Count | J17: Δ Change
A18: TC58 | B18: 118 | C18: 109 | D18: 1 | E18: 8 | G18: 118 | H18: =I18-G18 -> 0 | I18: =SUM(Table9[[#This Row],[Good]:[Lost]]) -> 118 | J18: =[1]Sheet5!$G$25 -> 0
A19: ET45 | B19: 72 | C19: 74 | G19: 75 | H19: =I19-G19 -> -1 | I19: =SUM(Table9[[#This Row],[Good]:[Lost]]) -> 74 | J19: =IF(B19<>"",I19-B19,"-") -> 2
A20: ET56 | B20: 73 | C20: 71 | G20: 67 | H20: =I20-G20 -> 4 | I20: =SUM(Table9[[#This Row],[Good]:[Lost]]) -> 71 | J20: =IF(B20<>"",I20-B20,"-") -> -2
A21: L10WA | B21: 60 | C21: 60 | G21: 51 | H21: =I21-G21 -> 9 | I21: =SUM(Table9[[#This Row],[Good]:[Lost]]) -> 60 | J21: =IF(B21<>"",I21-B21,"-") -> 0
A22: MC930 | B22: 26 | C22: 25 | E22: 1 | G22: 21 | H22: =I22-G22 -> 5 | I22: =SUM(Table9[[#This Row],[Good]:[Lost]]) -> 26 | J22: =IF(B22<>"",I22-B22,"-") -> 0
A23: Samsung | B23: 39 | C23: 47 | G23: 31 | H23: =I23-G23 -> 16 | I23: =SUM(Table9[[#This Row],[Good]:[Lost]]) -> 47 | J23: =IF(B23<>"",I23-B23,"-") -> 8
A24: TC57 | B24: 0 | C24: 0 | G24: 3 | H24: =I24-G24 -> -3 | I24: =SUM(Table9[[#This Row],[Good]:[Lost]]) -> 0 | J24: =IF(B24<>"",I24-B24,"-") -> 0
A25: RT10A | B25: 1 | C25: 1 | G25: 1 | H25: =I25-G25 -> 0 | I25: =SUM(Table9[[#This Row],[Good]:[Lost]]) -> 1 | J25: =IF(B25<>"",I25-B25,"-") -> 0
A26: TOTAL | B26: =SUM(Table9[Prior Count]) -> 389 | C26: =SUM(C18:C25) -> 387 | D26: =SUM(D18:D25) -> 1 | E26: =SUM(E18:E25) -> 9 | F26: =SUM(F18:F25) -> 0 | G26: =SUM(G18:G25) -> 367 | H26: =SUM(H18:H25) -> 30 | I26: =SUM(I18:I25) -> 397 | J26: =I26-B26 -> 8
A30: Total Accessories
A31: =B46 -> 703
A34: ACCESSORY INVENTORY BY TYPE
A35: Device Type | B35: Prior Count | C35: Good | D35: Bad | E35: RMA | F35: Lost | G35: Current Count | H35: Δ Change
A36: DS3608 | B36: 46 | C36: 46 | G36: =SUM(Table911[[#This Row],[Good]:[Lost]]) -> 46 | H36: =IF(B36<>" ",B36-G36) -> 0
A37: RS5100 | B37: 120 | C37: 118 | D37: 2 | G37: =SUM(Table911[[#This Row],[Good]:[Lost]]) -> 120 | H37: =IF(B37<>" ",B37-G37) -> 0
A38: RelayX | B38: 104 | C38: 117 | G38: =SUM(Table911[[#This Row],[Good]:[Lost]]) -> 117 | H38: =IF(B38<>" ",B38-G38) -> -13
A39: QP148454 | B39: 7 | C39: 8 | G39: =SUM(Table911[[#This Row],[Good]:[Lost]]) -> 8 | H39: =IF(B39<>" ",B39-G39) -> -1
A40: TC58 Accessory | B40: 36 | C40: 29 | D40: 7 | G40: =SUM(Table911[[#This Row],[Good]:[Lost]]) -> 36 | H40: =IF(B40<>" ",B40-G40) -> 0
A41: TC58 Battery | B41: 167 | C41: 167 | G41: =SUM(Table911[[#This Row],[Good]:[Lost]]) -> 167 | H41: =IF(B41<>" ",B41-G41) -> 0
A42: MC930 Battery | B42: 19 | C42: 19 | G42: =SUM(Table911[[#This Row],[Good]:[Lost]]) -> 19 | H42: =IF(B42<>" ",B42-G42) -> 0
A43: RS5100 Battery | B43: 141 | C43: 140 | D43: 1 | G43: =SUM(Table911[[#This Row],[Good]:[Lost]]) -> 141 | H43: =IF(B43<>" ",B43-G43) -> 0
A44: NX-1300 | B44: 24 | C44: 24 | G44: =SUM(Table911[[#This Row],[Good]:[Lost]]) -> 24 | H44: =IF(B44<>" ",B44-G44) -> 0
A45: VoCollect | B45: 39 | C45: 39 | G45: =SUM(Table911[[#This Row],[Good]:[Lost]]) -> 39 | H45: =IF(B45<>" ",B45-G45) -> 0
A46: TOTAL | B46: =SUM(B36:B45) -> 703 | C46: =SUM(C37:C44) -> 622 | D46: =SUM(D37:D44) -> 10 | E46: =SUM(E37:E44) -> 0 | F46: =SUM(F37:F44) -> 0 | G46: =SUM(G37:G44) -> 632 | H46: =SUM(H37:H44) -> -14
A51: NOT CONNECTED IN LAST 60 DAYS
A52: Justification | B52: Count | C52: Ticket
A53: Open Ticket to remove from GL | B53: 8 | C53: RITM10115486
A54: Open Ticket to remove from GL | B54: 1 | C54: RITM10128571
A55: New device on report - to audit | B55: 1 | C55: n/a
A56: Total | B56: 10 | C56: 2

Sheet Asset Detail
A1: Serial Number | B1: Asset Number | C1: Model | D1: Site Code | E1: Condition | F1: Status | G1: Shift | H1: Assigned User | I1: Last Scan Date | J1: GL | K1: Comment | L1: Audit Date | M1: Scanned
A2: 21440164 | C2: QP148454 | D2: PLCB | E2: G | I2: 45997 | L2: 45997
A3: 21440172 | C3: QP148454 | D3: PLCB | E3: G | I3: 45997 | L3: 45997
A4: 21450251 | C4: QP148454 | D4: PLCB | E4: G | I4: 45997 | L4: 45997
A5: 7820250328 | C5: VoCollect | D5: PLCB | E5: G | I5: 45997 | K5: No longer supported
A6: 7619443156 | C6: VoCollect | D6: PLCB | E6: G | I6: 45997 | K6: No longer supported
A7: 7620164063 | C7: VoCollect | D7: PLCB | E7: G | I7: 45997 | K7: No longer supported
A8: 7620164113 | C8: VoCollect | D8: PLCB | E8: G | I8: 45997 | K8: No longer supported
A9: 7620164123 | C9: VoCollect | D9: PLCB | E9: G | I9: 45997 | K9: No longer supported
A10: 7620245375 | C10: VoCollect | D10: PLCB | E10: G | I10: 45997 | K10: No longer supported
A11: 7620255473 | C11: VoCollect | D11: PLCB | E11: G | I11: 45997 | K11: No longer supported
A12: 7621127490 | C12: VoCollect | D12: PLCB | E12: G | I12: 45997 | K12: No longer supported
A13: 7621127521 | C13: VoCollect | D13: PLCB | E13: G | I13: 45997 | K13: No longer supported
A14: 7621320047 | C14: VoCollect | D14: PLCB | E14: G | I14: 45997 | K14: No longer supported
A15: 7621320049 | C15: VoCollect | D15: PLCB | E15: G | I15: 45997 | K15: No longer supported
A16: 7621320050 | C16: VoCollect | D16: PLCB | E16: G | I16: 45997 | K16: No longer supported
... A43: 7821390988 | C43: VoCollect | D43: PLCB | E43: G | I43: 45997 | K43: No longer supported
A44: 19353523600552 | C44: L10WA | D44: PLCB | E44: G | I44: 45997
A45: 19353523600553 | C45: L10WA | D45: PLCB | E45: G | I45: 45997
A46: 19353523600563 | C46: L10WA | D46: PLCB | E46: B | I46: 45997
A47: 19353523600579 | C47: L10WA | D47: PLCB | E47: G | I47: 45997
A48: 19353523600584 | C48: L10WA | D48: PLCB | E48: G | I48: 45997
A49: 19353523600589 | C49: L10WA | D49: PLCB | E49: G | I49: 45997
A50: 19353523600590 | C50: L10WA | D50: PLCB | E50: G | I50: 45997
A51: 19353523600592 | C51: L10WA | D51: PLCB | E51: G | I51: 45997
A52: 19353523600602 | C52: L10WA | D52: PLCB | E52: G | I52: 45997
A53: 19353523600603 | C53: L10WA | D53: PLCB | E53: G | I53: 45997
A54: 19353523600612 | C54: L10WA | D54: PLCB | E54: G | I54: 45997
A55: 19353523600620 | C55: L10WA | D55: PLCB | E55: G | I55: 45997
... A59: 19353523600633 | C59: L10WA | D59: PLCB | E59: G | I59: 45997
A60: 19353523600635 | C60: L10WA | D60: PLCB | E60: G | I60: 45997 | L60: 45997
A61: 19353523600636 | C61: L10WA | D61: PLCB | E61: G | I61: 45997
A62: 19353523600637 | C62: L10WA | D62: PLCB | E62: G | I62: 45997
A63: 19353523600643 | C63: L10WA | D63: PLCB | E63: G | I63: 45997
A64: 19353523600649 | C64: L10WA | D64: PLCB | E64: G | I64: 45997
A65: 20114522510250 | C65: MC930 | D65: PLCB | E65: G | I65: 45997
A66: 20114522519801 | C66: MC930 | D66: PLCB | E66: G | I66: 45997
A67: 20114522519866 | C67: MC930 | D67: PLCB | E67: G | I67: 45997
A68: 20114522519901 | C68: MC930 | D68: PLCB | E68: G | I68: 45997
A69: 20114522519954 | C69: MC930 | D69: PLCB | E69: G | I69: 45997
...

Sheet IT Allocation Import
A1: GL Substring: '61.5158*' (Filters = [dCO: '61', dCC: '5158'])
A2: GL String | B2: Category | C2: Amount | D2: Serial Number | E2: Detail1(UserVendor) | F2: Detail2(PRJ.) | G2: Country | H2: Sector | I2: Period | J2: Year | K2: 1MthAgo | L2: 2MthAgo | M2: 3MthAgo | N2: 4MthAgo | O2: 5MthAgo | P2: 6MthAgo | Q2: 7MthAgo | R2: 8MthAgo | S2: 9MthAgo | T2: 10MthAgo | U2: 11MthAgo | V2: 12MthAgo | W2: dCO | X2: dCC | Y2: dCU | Z2: dAC | AA2: dAT | AB2: dSA
A3: 61.5851.5531.8233.10.000 | B3: RF HARDWARE | C3: 0 | D3: 19149522503415 | E3: TC57 | F3: HSN: 19149522503415, MAC: c81cfe8c1278 | G3: US | H3: RETAIL CORE EXCL SLG | I3: 12 | J3: 2025 | K3: 0 | L3: 0 | M3: 0 | N3: 22.54 | O3: 22.54 | P3: 22.54 | Q3: 22.54 | R3: 22.54 | S3: 22.54 | T3: 22.54 | U3: 22.54 | V3: 22.54 | W3: 61 | X3: 5851 | Y3: 5531 | Z3: 8233 | AA3: 10 | AB3: 000
A4: 61.5851.5531.8233.10.000 | B4: RF HARDWARE | C4: 0 | D4: 19172522500971 | E4: TC57 | F4: HSN: 19172522500971, MAC: 94FB298DAAFC | G4: US | H4: RETAIL CORE EXCL SLG | I4: 12 | J4: 2025 | K4: 22.54 | L4: 22.54 | M4: 22.54 | N4: 22.54 | O4: 22.54 | P4: 22.54 | Q4: 22.54 | R4: 22.54 | S4: 22.54 | T4: 22.54 | U4: 22.54 | V4: 22.54 | W4: 61 | X4: 5851 | Y4: 5531 | Z4: 8233 | AA4: 10 | AB4: 000
A5: 61.5851.5531.8233.10.000 | B5: RF HARDWARE | C5: 0 | D5: 19172522501070 | E5: TC57 | F5: HSN: 19172522501070, MAC: 94fb298ddf00 | G5: US | H5: RETAIL CORE EXCL SLG | I5: 12 | J5: 2025 | K5: 0 | L5: 0 | M5: 0 | N5: 22.54 | O5: 22.54 | P5: 22.54 | Q5: 22.54 | R5: 22.54 | S5: 22.54 | T5: 22.54 | U5: 22.54 | V5: 22.54 | W5: 61 | X5: 5851 | Y5: 5531 | Z5: 8233 | AA5: 10 | AB5: 000
A6: 61.5851.5531.8233.10.000 | B6: RF HARDWARE | C6: 0 | D6: 19172522501096 | E6: TC57 | F6: HSN: 19172522501096, MAC: 94fb2992bfea | G6: US | H6: RETAIL CORE EXCL SLG | I6: 12 | J6: 2025 | K6: 22.54 | L6: 22.54 | M6: 22.54 | N6: 22.54 | O6: 22.54 | P6: 22.54 | Q6: 22.54 | R6: 22.54 | S6: 22.54 | T6: 22.54 | U6: 22.54 | V6: 22.54 | W6: 61 | X6: 5851 | Y6: 5531 | Z6: 8233 | AA6: 10 | AB6: 000
A7: 61.5851.5531.8233.10.000 | B7: RF HARDWARE | C7: 0 | D7: 19172522501101 | E7: TC57 | F7: HSN: 19172522501101, MAC: 94fb298dddbb | G7: US | H7: RETAIL CORE EXCL SLG | I7: 12 | J7: 2025 | K7: 0 | L7: 0 | M7: 0 | N7: 22.54 | O7: 22.54 | P7: 22.54 | Q7: 22.54 | R7: 22.54 | S7: 22.54 | T7: 22.54 | U7: 22.54 | V7: 22.54 | W7: 61 | X7: 5851 | Y7: 5531 | Z7: 8233 | AA7: 10 | AB7: 000
A8: 61.5851.5531.8233.10.000 | B8: RF HARDWARE | C8: 0 | D8: 19187522500435 | E8: TC57 | F8: HSN: 19187522500435, MAC: 94fb298f5c18 | G8: US | H8: RETAIL CORE EXCL SLG | I8: 12 | J8: 2025 | K8: 0 | L8: 0 | M8: 0 | N8: 22.54 | O8: 22.54 | P8: 22.54 | Q8: 22.54 | R8: 22.54 | S8: 22.54 | T8: 22.54 | U8: 22.54 | V8: 22.54 | W8: 61 | X8: 5851 | Y8: 5531 | Z8: 8233 | AA8: 10 | AB8: 000
A9: 61.5851.5531.8233.10.000 | B9: RF HARDWARE | C9: 0 | D9: 19187522504542 | E9: TC57 | F9: HSN: 19187522504542, MAC: 94fb298f5dcf | G9: US | H9: RETAIL CORE EXCL SLG | I9: 12 | J9: 2025 | K9: 0 | L9: 0 | M9: 0 | N9: 22.54 | O9: 22.54 | P9: 22.54 | Q9: 22.54 | R9: 22.54 | S9: 22.54 | T9: 22.54 | U9: 22.54 | V9: 22.54 | W9: 61 | X9: 5851 | Y9: 5531 | Z9: 8233 | AA9: 10 | AB9: 000
A10: 61.5851.5531.8233.10.000 | B10: RF HARDWARE | C10: 0 | D10: 19187522504630 | E10: TC57 | F10: HSN: 19187522504630, MAC: 78b8d6900f29 | G10: US | H10: RETAIL CORE EXCL SLG | I10: 12 | J10: 2025 | K10: 0 | L10: 0 | M10: 22.54 | N10: 22.54 | O10: 22.54 | P10: 22.54 | Q10: 22.54 | R10: 22.54 | S10: 22.54 | T10: 22.54 | U10: 22.54 | V10: 0 | W10: 61 | X10: 5851 | Y10: 5531 | Z10: 8233 | AA10: 10 | AB10: 000
A11: 61.5851.5531.8233.10.000 | B11: RF HARDWARE | C11: 0 | D11: 19187522504962 | E11: TC57 | F11: HSN: 19187522504962, MAC: 94fb298fa742 | G11: US | H11: RETAIL CORE EXCL SLG | I11: 12 | J11: 2025 | K11: 0 | L11: 0 | M11: 0 | N11: 22.54 | O11: 22.54 | P11: 22.54 | Q11: 22.54 | R11: 22.54 | S11: 22.54 | T11: 22.54 | U11: 22.54 | V11: 22.54 | W11: 61 | X11: 5851 | Y11: 5531 | Z11: 8233 | AA11: 10 | AB11: 000
A12: 61.5851.5531.8233.10.000 | B12: RF HARDWARE | C12: 0 | D12: 19201522506033 | E12: TC57 | F12: HSN: 19201522506033, MAC: c81cfeeee0ef | G12: US | H12: RETAIL CORE EXCL SLG | I12: 12 | J12: 2025 | K12: 0 | L12: 0 | M12: 0 | N12: 22.54 | O12: 22.54 | P12: 22.54 | Q12: 22.54 | R12: 22.54 | S12: 22.54 | T12: 22.54 | U12: 22.54 | V12: 22.54 | W12: 61 | X12: 5851 | Y12: 5531 | Z12: 8233 | AA12: 10 | AB12: 000
A13: 61.5851.5531.8233.10.000 | B13: RF HARDWARE | C13: 0 | D13: 19220522500569 | E13: TC57 | F13: HSN: 19220522500569, MAC: 94fb2992b411 | G13: US | H13: RETAIL CORE EXCL SLG | I13: 12 | J13: 2025 | K13: 0 | L13: 0 | M13: 0 | N13: 22.54 | O13: 22.54 | P13: 22.54 | Q13: 22.54 | R13: 22.54 | S13: 22.54 | T13: 22.54 | U13: 22.54 | V13: 22.54 | W13: 61 | X13: 5851 | Y13: 5531 | Z13: 8233 | AA13: 10 | AB13: 000
A14: 61.5851.5531.8233.10.000 | B14: RF HARDWARE | C14: 0 | D14: 19220522500721 | E14: TC57 | F14: HSN: 19220522500721, MAC: c81cfe8d1c29 | G14: US | H14: RETAIL CORE EXCL SLG | I14: 12 | J14: 2025 | K14: 0 | L14: 22.54 | M14: 22.54 | N14: 22.54 | O14: 22.54 | P14: 22.54 | Q14: 22.54 | R14: 22.54 | S14: 22.54 | T14: 22.54 | U14: 22.54 | V14: 22.54 | W14: 61 | X14: 5851 | Y14: 5531 | Z14: 8233 | AA14: 10 | AB14: 000
... A441: 61.5851.5531.8233.20.000 | B441: RF HARDWARE | C441: 0 | D441: 22292524701380 | E441: ET45 | F441: HSN: 22292524701380, MAC: c81cfe30e82c | G441: US | H441: RETAIL CORE EXCL SLG | I441: 12 | J441: 2025 | K441: 27.49 | L441: 27.49 | M441: 27.49 | N441: 27.49 | O441: 27.49 | P441: 27.49 | Q441: 27.49 | R441: 27.49 | S441: 27.49 | T441: 27.49 | U441: 27.49 | V441: 27.49 | W441: 61 | X441: 5851 | Y441: 5531 | Z441: 8233 | AA441: 20 | AB441: 000

Sheet PBI Import
A1: PBI CONNECTION STATUS IMPORT
A3: PASTE 2 COLUMNS FROM YOUR PBI/SOTI EXPORT:
A4: Column A = SerialNumber | Column B = 'Connected in last 60 days' or 'Not connected in last 60 days'
A6: Records | B6: Connected | C6: Not Connected
A7: =COUNTA(A10:A500) -> 367 | B7: =COUNTIF(B10:B500,"Connected in last 60 days") -> 357 | C7: =COUNTIF(B10:B500,"Not Connected in last 60 days") -> 10
A9: SN | B9: Status | C9: Model | D9: Justification | E9: Ticket
A10: 23055R0183 | B10: Connected in last 60 days | C10: RT10A
A11: R52MB144KNX | B11: Connected in last 60 days | C11: SM-T387P
A12: R52MB144EDA | B12: Connected in last 60 days | C12: SM-T387P
A13: R52MB144LFH | B13: Connected in last 60 days | C13: SM-T387P
A14: R52R505TYGH | B14: Connected in last 60 days | C14: SM-T307U
A15: R52R504F5DH | B15: Connected in last 60 days | C15: SM-T307U
A16: R52R504K3YR | B16: Connected in last 60 days | C16: SM-T307U
A17: R52R5030A9N | B17: Connected in last 60 days | C17: SM-T307U
A18: R52R504E3QA | B18: Not Connected in last 60 days | C18: SM-T307U | D18: New device on report - to audit | E18: N/A
A19: R52R504H36R | B19: Connected in last 60 days | C19: SM-T307U
A20: R52R503479J | B20: Connected in last 60 days | C20: SM-T307U
A21: R52R505Q1ZA | B21: Connected in last 60 days | C21: SM-T307U
A22: R52R502ZE6L | B22: Connected in last 60 days | C22: SM-T307U
A23: R52R5030T4B | B23: Connected in last 60 days | C23: SM-T307U
A24: R52R504D3YB | B24: Connected in last 60 days | C24: SM-T307U
A25: R52R504C8FW | B25: Connected in last 60 days | C25: SM-T307U
A26: R52R504DP6W | B26: Connected in last 60 days | C26: SM-T307U
A27: R52R505QV9B | B27: Connected in last 60 days | C27: SM-T307U
A28: R52R505Y9PT | B28: Connected in last 60 days | C28: SM-T307U
A29: R52R504DQTA | B29: Connected in last 60 days | C29: SM-T307U
A30: R52R505V0NA | B30: Connected in last 60 days | C30: SM-T307U
... A50: 22293524700004 | B50: Connected in last 60 days | C50: ET45
A51: 22293524700443 | B51: Not Connected in last 60 days | C51: ET45 | D51: Open Ticket to remove from GL | E51: RITM10115486
A52: 22292524701380 | B52: Connected in last 60 days | C52: ET45
A53: 22293524701850 | B53: Connected in last 60 days | C53: ET45
A54: 22294524700112 | B54: Connected in last 60 days | C54: ET45
A55: 22293524701318 | B55: Connected in last 60 days | C55: ET45
A56: 22280524700896 | B56: Connected in last 60 days | C56: ET45
A57: 22293524701715 | B57: Connected in last 60 days | C57: ET45
A58: 22293524701571 | B58: Connected in last 60 days | C58: ET45
A59: 22293524701485 | B59: Connected in last 60 days | C59: ET45
A60: 22293524700476 | B60: Connected in last 60 days | C60: ET45
A61: 22293524700411 | B61: Connected in last 60 days | C61: ET45
A62: 22293524700303 | B62: Connected in last 60 days | C62: ET45
...

Sheet Scan Audit
A1: PHYSICAL AUDIT - SCAN ENTRY
A3: Scan or enter Asset Numbers below. System will auto-match against Asset Detail inventory.
A5: Total Scanned | B5: Found in System | C5: Not in System | D5: Expected from Asset Details | E5: Not Yet Scanned | F5: Audit Progress
A6: =ROWS(A9:A1112) -> 1104 | B6: =COUNTIF(E9:E1112,"✓ Found") -> 51 | C6: =COUNTIF(E9:E1112,"✗ Not Found") -> 0 | D6: =COUNTA('Asset Detail'!A2:A1095) -> 1094 | E6: =D6-B6 -> 1043 | F6: =IFERROR(B6/D6,0) -> 0.046617916
A8: Serial Number | B8: Scan Date | C8: Scanned By | D8: Location | E8: Match Status | F8: Model (from System) | G8: Condition (System) | H8: Notes | I8: Scan
A9: =SUBSTITUTE(I9, "S", "") -> 21195523600068 | D9: KLS | E9: =IF(A9="","",IF(COUNTIF('Asset Detail'!A:A,A9)>0,"✓ Found","✗ Not Found")) -> ✓ Found | F9: {=IF(A9="","",IFERROR(INDEX('Asset Detail'!C:C,_xlfn.XMATCH(A9,'Asset Detail'!A:A,3)),"—"))} -> L10WA | G9: {=IF(A9="","",IFERROR(INDEX('Asset Detail'!E:E,_xlfn.XMATCH(A9,'Asset Detail'!A:A,3)),"—"))} -> G | I9: 21195523600068
A10: =SUBSTITUTE(I10, "S", "") -> 18339523080026 | D10: KLS | E10: =IF(A10="","",IF(COUNTIF('Asset Detail'!A:A,A10)>0,"✓ Found","✗ Not Found")) -> ✓ Found | F10: {=IF(A10="","",IFERROR(INDEX('Asset Detail'!C:C,_xlfn.XMATCH(A10,'Asset Detail'!A:A,3)),"—"))} -> DS3608 | G10: {=IF(A10="","",IFERROR(INDEX('Asset Detail'!E:E,_xlfn.XMATCH(A10,'Asset Detail'!A:A,3)),"—"))} -> G | I10: 18339523080026
A11: =SUBSTITUTE(I11, "S", "") -> 22167523600602 | D11: KLS | E11: =IF(A11="","",IF(COUNTIF('Asset Detail'!A:A,A11)>0,"✓ Found","✗ Not Found")) -> ✓ Found | F11: {=IF(A11="","",IFERROR(INDEX('Asset Detail'!C:C,_xlfn.XMATCH(A11,'Asset Detail'!A:A,3)),"—"))} -> L10WA | G11: {=IF(A11="","",IFERROR(INDEX('Asset Detail'!E:E,_xlfn.XMATCH(A11,'Asset Detail'!A:A,3)),"—"))} -> G | I11: 22167523600602
A12: =SUBSTITUTE(I12, "S", "") -> 22139523601892 | D12: KLS | E12: =IF(A12="","",IF(COUNTIF('Asset Detail'!A:A,A12)>0,"✓ Found","✗ Not Found")) -> ✓ Found | F12: {=IF(A12="","",IFERROR(INDEX('Asset Detail'!C:C,_xlfn.XMATCH(A12,'Asset Detail'!A:A,3)),"—"))} -> ET56 | G12: {=IF(A12="","",IFERROR(INDEX('Asset Detail'!E:E,_xlfn.XMATCH(A12,'Asset Detail'!A:A,3)),"—"))} -> G | I12: S22139523601892
A13: =SUBSTITUTE(I13, "S", "") -> 21103523601019 | D13: KLS | E13: =IF(A13="","",IF(COUNTIF('Asset Detail'!A:A,A13)>0,"✓ Found","✗ Not Found")) -> ✓ Found | F13: {=IF(A13="","",IFERROR(INDEX('Asset Detail'!C:C,_xlfn.XMATCH(A13,'Asset Detail'!A:A,3)),"—"))} -> ET56 | G13: {=IF(A13="","",IFERROR(INDEX('Asset Detail'!E:E,_xlfn.XMATCH(A13,'Asset Detail'!A:A,3)),"—"))} -> G | I13: S21103523601019
A14: =SUBSTITUTE(I14, "S", "") -> 19353523600635 | D14: KLS | E14: =IF(A14="","",IF(COUNTIF('Asset Detail'!A:A,A14)>0,"✓ Found","✗ Not Found")) -> ✓ Found | F14: {=IF(A14="","",IFERROR(INDEX('Asset Detail'!C:C,_xlfn.XMATCH(A14,'Asset Detail'!A:A,3)),"—"))} -> L10WA | G14: {=IF(A14="","",IFERROR(INDEX('Asset Detail'!E:E,_xlfn.XMATCH(A14,'Asset Detail'!A:A,3)),"—"))} -> G | I14: 19353523600635
A15: =SUBSTITUTE(I15, "S", "") -> 21218520180895 | D15: KLS | E15: =IF(A15="","",IF(COUNTIF('Asset Detail'!A:A,A15)>0,"✓ Found","✗ Not Found")) -> ✓ Found | F15: {=IF(A15="","",IFERROR(INDEX('Asset Detail'!C:C,_xlfn.XMATCH(A15,'Asset Detail'!A:A,3)),"—"))} -> DS3608 | G15: {=IF(A15="","",IFERROR(INDEX('Asset Detail'!E:E,_xlfn.XMATCH(A15,'Asset Detail'!A:A,3)),"—"))} -> G | I15: 21218520180895
A16: =SUBSTITUTE(I16, "S", "") -> 21218520180904 | D16: KLS | E16: =IF(A16="","",IF(COUNTIF('Asset Detail'!A:A,A16)>0,"✓ Found","✗ Not Found")) -> ✓ Found | F16: {=IF(A16="","",IFERROR(INDEX('Asset Detail'!C:C,_xlfn.XMATCH(A16,'Asset Detail'!A:A,3)),"—"))} -> DS3608 | G16: {=IF(A16="","",IFERROR(INDEX('Asset Detail'!E:E,_xlfn.XMATCH(A16,'Asset Detail'!A:A,3)),"—"))} -> G | I16: 21218520180904
A17: =SUBSTITUTE(I17, "S", "") -> 21200523601003 | D17: KLS | E17: =IF(A17="","",IF(COUNTIF('Asset Detail'!A:A,A17)>0,"✓ Found","✗ Not Found")) -> ✓ Found | F17: {=IF(A17="","",IFERROR(INDEX('Asset Detail'!C:C,_xlfn.XMATCH(A17,'Asset Detail'!A:A,3)),"—"))} -> L10WA | G17: {=IF(A17="","",IFERROR(INDEX('Asset Detail'!E:E,_xlfn.XMATCH(A17,'Asset Detail'!A:A,3)),"—"))} -> G | I17: 21200523601003
A18: =SUBSTITUTE(I18, "S", "") -> 21218520180908 | D18: KLS | E18: =IF(A18="","",IF(COUNTIF('Asset Detail'!A:A,A18)>0,"✓ Found","✗ Not Found")) -> ✓ Found | F18: {=IF(A18="","",IFERROR(INDEX('Asset Detail'!C:C,_xlfn.XMATCH(A18,'Asset Detail'!A:A,3)),"—"))} -> DS3608 | G18: {=IF(A18="","",IFERROR(INDEX('Asset Detail'!E:E,_xlfn.XMATCH(A18,'Asset Detail'!A:A,3)),"—"))} -> G | I18: 21218520180908
A19: =SUBSTITUTE(I19, "S", "") -> 21195523600092 | D19: KLS | E19: =IF(A19="","",IF(COUNTIF('Asset Detail'!A:A,A19)>0,"✓ Found","✗ Not Found")) -> ✓ Found | F19: {=IF(A19="","",IFERROR(INDEX('Asset Detail'!C:C,_xlfn.XMATCH(A19,'Asset Detail'!A:A,3)),"—"))} -> L10WA | G19: {=IF(A19="","",IFERROR(INDEX('Asset Detail'!E:E,_xlfn.XMATCH(A19,'Asset Detail'!A:A,3)),"—"))} -> G | I19: 21195523600092
A20: =SUBSTITUTE(I20, "S", "") -> 21224520180495 | D20: KLS | E20: =IF(A20="","",IF(COUNTIF('Asset Detail'!A:A,A20)>0,"✓ Found","✗ Not Found")) -> ✓ Found | F20: {=IF(A20="","",IFERROR(INDEX('Asset Detail'!C:C,_xlfn.XMATCH(A20,'Asset Detail'!A:A,3)),"—"))} -> DS3608 | G20: {=IF(A20="","",IFERROR(INDEX('Asset Detail'!E:E,_xlfn.XMATCH(A20,'Asset Detail'!A:A,3)),"—"))} -> G | I20: 21224520180495
A21: =SUBSTITUTE(I21, "S", "") -> 19353523600592 | D21: KLS | E21: =IF(A21="","",IF(COUNTIF('Asset Detail'!A:A,A21)>0,"✓ Found","✗ Not Found")) -> ✓ Found | F21: {=IF(A21="","",IFERROR(INDEX('Asset Detail'!C:C,_xlfn.XMATCH(A21,'Asset Detail'!A:A,3)),"—"))} -> L10WA | G21: {=IF(A21="","",IFERROR(INDEX('Asset Detail'!E:E,_xlfn.XMATCH(A21,'Asset Detail'!A:A,3)),"—"))} -> G | I21: 19353523600592
A22: =SUBSTITUTE(I22, "S", "") -> 19353523600633 | D22: KLS | E22: =IF(A22="","",IF(COUNTIF('Asset Detail'!A:A,A22)>0,"✓ Found","✗ Not Found")) -> ✓ Found | F22: {=IF(A22="","",IFERROR(INDEX('Asset Detail'!C:C,_xlfn.XMATCH(A22,'Asset Detail'!A:A,3)),"—"))} -> L10WA | G22: {=IF(A22="","",IFERROR(INDEX('Asset Detail'!E:E,_xlfn.XMATCH(A22,'Asset Detail'!A:A,3)),"—"))} -> G | I22: 19353523600633
A23: =SUBSTITUTE(I23, "S", "") -> 18338523081888 | D23: KLS | E23: =IF(A23="","",IF(COUNTIF('Asset Detail'!A:A,A23)>0,"✓ Found","✗ Not Found")) -> ✓ Found | F23: {=IF(A23="","",IFERROR(INDEX('Asset Detail'!C:C,_xlfn.XMATCH(A23,'Asset Detail'!A:A,3)),"—"))} -> DS3608 | G23: {=IF(A23="","",IFERROR(INDEX('Asset Detail'!E:E,_xlfn.XMATCH(A23,'Asset Detail'!A:A,3)),"—"))} -> G | I23: S18338523081888
A24: =SUBSTITUTE(I24, "S", "") -> 21195523600030 | D24: KLS | E24: =IF(A24="","",IF(COUNTIF('Asset Detail'!A:A,A24)>0,"✓ Found","✗ Not Found")) -> ✓ Found | F24: {=IF(A24="","",IFERROR(INDEX('Asset Detail'!C:C,_xlfn.XMATCH(A24,'Asset Detail'!A:A,3)),"—"))} -> L10WA | G24: {=IF(A24="","",IFERROR(INDEX('Asset Detail'!E:E,_xlfn.XMATCH(A24,'Asset Detail'!A:A,3)),"—"))} -> G | I24: 21195523600030
A25: =SUBSTITUTE(I25, "S", "") -> 19353523600589 | D25: KLS | E25: =IF(A25="","",IF(COUNTIF('Asset Detail'!A:A,A25)>0,"✓ Found","✗ Not Found")) -> ✓ Found | F25: {=IF(A25="","",IFERROR(INDEX('Asset Detail'!C:C,_xlfn.XMATCH(A25,'Asset Detail'!A:A,3)),"—"))} -> L10WA | G25: {=IF(A25="","",IFERROR(INDEX('Asset Detail'!E:E,_xlfn.XMATCH(A25,'Asset Detail'!A:A,3)),"—"))} -> G | I25: 19353523600589
A26: =SUBSTITUTE(I26, "S", "") -> 21200523600621 | D26: KLS | E26: =IF(A26="","",IF(COUNTIF('Asset Detail'!A:A,A26)>0,"✓ Found","✗ Not Found")) -> ✓ Found | F26: {=IF(A26="","",IFERROR(INDEX('Asset Detail'!C:C,_xlfn.XMATCH(A26,'Asset Detail'!A:A,3)),"—"))} -> L10WA | G26: {=IF(A26="","",IFERROR(INDEX('Asset Detail'!E:E,_xlfn.XMATCH(A26,'Asset Detail'!A:A,3)),"—"))} -> G | I26: 21200523600621
A27: =SUBSTITUTE(I27, "S", "") -> 21195523600007 | D27: KLS | E27: =IF(A27="","",IF(COUNTIF('Asset Detail'!A:A,A27)>0,"✓ Found","✗ Not Found")) -> ✓ Found | F27: {=IF(A27="","",IFERROR(INDEX('Asset Detail'!C:C,_xlfn.XMATCH(A27,'Asset Detail'!A:A,3)),"—"))} -> L10WA | G27: {=IF(A27="","",IFERROR(INDEX('Asset Detail'!E:E,_xlfn.XMATCH(A27,'Asset Detail'!A:A,3)),"—"))} -> G | I27: 21195523600007
A28: =SUBSTITUTE(I28, "S", "") -> 21195523600081 | D28: KLS | E28: =IF(A28="","",IF(COUNTIF('Asset Detail'!A:A,A28)>0,"✓ Found","✗ Not Found")) -> ✓ Found | F28: {=IF(A28="","",IFERROR(INDEX('Asset Detail'!C:C,_xlfn.XMATCH(A28,'Asset Detail'!A:A,3)),"—"))} -> L10WA | G28: {=IF(A28="","",IFERROR(INDEX('Asset Detail'!E:E,_xlfn.XMATCH(A28,'Asset Detail'!A:A,3)),"—"))} -> G | I28: 21195523600081
A29: =SUBSTITUTE(I29, "S", "") -> 22167523600739 | D29: KLS | E29: =IF(A29="","",IF(COUNTIF('Asset Detail'!A:A,A29)>0,"✓ Found","✗ Not Found")) -> ✓ Found | F29: {=IF(A29="","",IFERROR(INDEX('Asset Detail'!C:C,_xlfn.XMATCH(A29,'Asset Detail'!A:A,3)),"—"))} -> L10WA | G29: {=IF(A29="","",IFERROR(INDEX('Asset Detail'!E:E,_xlfn.XMATCH(A29,'Asset Detail'!A:A,3)),"—"))} -> G | I29: 22167523600739
A30: =SUBSTITUTE(I30, "S", "") -> 22161523600084 | D30: KLS | E30: =IF(A30="","",IF(COUNTIF('Asset Detail'!A:A,A30)>0,"✓ Found","✗ Not Found")) -> ✓ Found | F30: {=IF(A30="","",IFERROR(INDEX('Asset Detail'!C:C,_xlfn.XMATCH(A30,'Asset Detail'!A:A,3)),"—"))} -> L10WA | G30: {=IF(A30="","",IFERROR(INDEX('Asset Detail'!E:E,_xlfn.XMATCH(A30,'Asset Detail'!A:A,3)),"—"))} -> G | I30: 22161523600084
A31: =SUBSTITUTE(I31, "S", "") -> 19353523600611 | D31: KLS | E31: =IF(A31="","",IF(COUNTIF('Asset Detail'!A:A,A31)>0,"✓ Found","✗ Not Found")) -> ✓ Found | F31: {=IF(A31="","",IFERROR(INDEX('Asset Detail'!C:C,_xlfn.XMATCH(A31,'Asset Detail'!A:A,3)),"—"))} -> L10WA | G31: {=IF(A31="","",IFERROR(INDEX('Asset Detail'!E:E,_xlfn.XMATCH(A31,'Asset Detail'!A:A,3)),"—"))} -> G | I31: 19353523600611
A32: =SUBSTITUTE(I32, "S", "") -> 19353523600641 | D32: KLS | E32: =IF(A32="","",IF(COUNTIF('Asset Detail'!A:A,A32)>0,"✓ Found","✗ Not Found")) -> ✓ Found | F32: {=IF(A32="","",IFERROR(INDEX('Asset Detail'!C:C,_xlfn.XMATCH(A32,'Asset Detail'!A:A,3)),"—"))} -> L10WA | G32: {=IF(A32="","",IFERROR(INDEX('Asset Detail'!E:E,_xlfn.XMATCH(A32,'Asset Detail'!A:A,3)),"—"))} -> G | I32: 19353523600641
A33: =SUBSTITUTE(I33, "S", "") -> 20132523600135 | D33: KLS | E33: =IF(A33="","",IF(COUNTIF('Asset Detail'!A:A,A33)>0,"✓ Found","✗ Not Found")) -> ✓ Found | F33: {=IF(A33="","",IFERROR(INDEX('Asset Detail'!C:C,_xlfn.XMATCH(A33,'Asset Detail'!A:A,3)),"—"))} -> L10WA | G33: {=IF(A33="","",IFERROR(INDEX('Asset Detail'!E:E,_xlfn.XMATCH(A33,'Asset Detail'!A:A,3)),"—"))} -> G | I33: 20132523600135
A34: =SUBSTITUTE(I34, "S", "") -> 21195523600019 | D34: KLS | E34: =IF(A34="","",IF(COUNTIF('Asset Detail'!A:A,A34)>0,"✓ Found","✗ Not Found")) -> ✓ Found | F34: {=IF(A34="","",IFERROR(INDEX('Asset Detail'!C:C,_xlfn.XMATCH(A34,'Asset Detail'!A:A,3)),"—"))} -> L10WA | G34: {=IF(A34="","",IFERROR(INDEX('Asset Detail'!E:E,_xlfn.XMATCH(A34,'Asset Detail'!A:A,3)),"—"))} -> G | I34: 21195523600019
A35: =SUBSTITUTE(I35, "S", "") -> 19353523600637 | D35: KLS | E35: =IF(A35="","",IF(COUNTIF('Asset Detail'!A:A,A35)>0,"✓ Found","✗ Not Found")) -> ✓ Found | F35: {=IF(A35="","",IFERROR(INDEX('Asset Detail'!C:C,_xlfn.XMATCH(A35,'Asset Detail'!A:A,3)),"—"))} -> L10WA | G35: {=IF(A35="","",IFERROR(INDEX('Asset Detail'!E:E,_xlfn.XMATCH(A35,'Asset Detail'!A:A,3)),"—"))} -> G | I35: 19353523600637
... A53: =SUBSTITUTE(I53, "S", "") -> 21224520180488 | D53: KLS | E53: =IF(A53="","",IF(COUNTIF('Asset Detail'!A:A,A53)>0,"✓ Found","✗ Not Found")) -> ✓ Found | F53: {=IF(A53="","",IFERROR(INDEX('Asset Detail'!C:C,_xlfn.XMATCH(A53,'Asset Detail'!A:A,3)),"—"))} -> DS3608 | G53: {=IF(A53="","",IFERROR(INDEX('Asset Detail'!E:E,_xlfn.XMATCH(A53,'Asset Detail'!A:A,3)),"—"))} -> G | I53: 21224520180488
A54: =SUBSTITUTE(I54, "S", "") -> 22353523601280 | D54: KLS | E54: =IF(A54="","",IF(COUNTIF('Asset Detail'!A:A,A54)>0,"✓ Found","✗ Not Found")) -> ✓ Found | F54: {=IF(A54="","",IFERROR(INDEX('Asset Detail'!C:C,_xlfn.XMATCH(A54,'Asset Detail'!A:A,3)),"—"))} -> ET56 | G54: {=IF(A54="","",IFERROR(INDEX('Asset Detail'!E:E,_xlfn.XMATCH(A54,'Asset Detail'!A:A,3)),"—"))} -> G | I54: S22353523601280
A55: =SUBSTITUTE(I55, "S", "") -> 21342523600189 | D55: KLS | E55: =IF(A55="","",IF(COUNTIF('Asset Detail'!A:A,A55)>0,"✓ Found","✗ Not Found")) -> ✓ Found | F55: {=IF(A55="","",IFERROR(INDEX('Asset Detail'!C:C,_xlfn.XMATCH(A55,'Asset Detail'!A:A,3)),"—"))} -> ET56 | G55: {=IF(A55="","",IFERROR(INDEX('Asset Detail'!E:E,_xlfn.XMATCH(A55,'Asset Detail'!A:A,3)),"—"))} -> G | I55: S21342523600189
A56: =SUBSTITUTE(I56, "S", "") -> 21112523600612 | D56: KLS | E56: =IF(A56="","",IF(COUNTIF('Asset Detail'!A:A,A56)>0,"✓ Found","✗ Not Found")) -> ✓ Found | F56: {=IF(A56="","",IFERROR(INDEX('Asset Detail'!C:C,_xlfn.XMATCH(A56,'Asset Detail'!A:A,3)),"—"))} -> ET56 | G56: {=IF(A56="","",IFERROR(INDEX('Asset Detail'!E:E,_xlfn.XMATCH(A56,'Asset Detail'!A:A,3)),"—"))} -> G | I56: S21112523600612
A57: =SUBSTITUTE(I57, "S", "") | D57: KLS | E57: =IF(A57="","",IF(COUNTIF('Asset Detail'!A:A,A57)>0,"✓ Found","✗ Not Found")) | F57: {=IF(A57="","",IFERROR(INDEX('Asset Detail'!C:C,_xlfn.XMATCH(A57,'Asset Detail'!A:A,3)),"—"))} | G57: {=IF(A57="","",IFERROR(INDEX('Asset Detail'!E:E,_xlfn.XMATCH(A57,'Asset Detail'!A:A,3)),"—"))}
A58: =SUBSTITUTE(I58, "S", "") | D58: KLS | E58: =IF(A58="","",IF(COUNTIF('Asset Detail'!A:A,A58)>0,"✓ Found","✗ Not Found")) | F58: {=IF(A58="","",IFERROR(INDEX('Asset Detail'!C:C,_xlfn.XMATCH(A58,'Asset Detail'!A:A,3)),"—"))} | G58: {=IF(A58="","",IFERROR(INDEX('Asset Detail'!E:E,_xlfn.XMATCH(A58,'Asset Detail'!A:A,3)),"—"))}
A59: =SUBSTITUTE(I59, "S", "") | D59: KLS | E59: =IF(A59="","",IF(COUNTIF('Asset Detail'!A:A,A59)>0,"✓ Found","✗ Not Found")) | F59: {=IF(A59="","",IFERROR(INDEX('Asset Detail'!C:C,_xlfn.XMATCH(A59,'Asset Detail'!A:A,3)),"—"))} | G59: {=IF(A59="","",IFERROR(INDEX('Asset Detail'!E:E,_xlfn.XMATCH(A59,'Asset Detail'!A:A,3)),"—"))}
A60: =SUBSTITUTE(I60, "S", "") | D60: KLS | E60: =IF(A60="","",IF(COUNTIF('Asset Detail'!A:A,A60)>0,"✓ Found","✗ Not Found")) | F60: {=IF(A60="","",IFERROR(INDEX('Asset Detail'!C:C,_xlfn.XMATCH(A60,'Asset Detail'!A:A,3)),"—"))} | G60: {=IF(A60="","",IFERROR(INDEX('Asset Detail'!E:E,_xlfn.XMATCH(A60,'Asset Detail'!A:A,3)),"—"))}
...

Sheet Lost Report
A1: MISSING ASSETS REPORT
A3: Assets in system that were NOT scanned during physical audit. Review after audit completion.
A5: Serial Number | B5: Model | C5: Last Known Scan | D5: Assigned User | E5: Last Scan Date | F5: Action Required

Sheet RMA Report
A1: RMA ASSET REPORT
A3: KEY PERFORMANCE INDICATORS
A4: Total Assets | B4: Shipped | C4: Received | D4: Compliance | E4: Assets still in RMA | F4: RMA Completed
A5: =COUNTA(A10:A100) -> 16 | B5: =COUNTA(F10:F100) -> 16 | C5: =COUNTA(H10:H100) -> 15 | D5: =IFERROR(C5/B5,0) -> 0.9375 | E5: =IFERROR(B5-C5,0) -> 1 | F5: =COUNTA(G10:G100) -> 15
A9: Serial Number | B9: Model | C9: Issue | D9: RMA Number | E9: Date Created | F9: Shipped Date | G9: Est. Received Date. | H9: Actual Received Date | I9: Received Serial Number
A10: 22348522507422 | B10: Hand Held (TC58) | C10: Barcode is not showing, and a random light come on. | D10: B479596-200602178 | E10: 45996 | F10: 45999 | G10: 46022 | H10: 46022 | I10: 22348522507422
A11: 22332522506104 | B11: Hand Held (TC58) | C11: Barcode scanner laser is not showing. | D11: B479595-200602171 | E11: 45996 | F11: 45999 | G11: 46036 | H11: 46037 | I11: 22332522506104
A12: 22348522507332 | B12: Hand Held (TC58) | C12: Will not power on. | D12: B477572-200554010 | E12: 45979 | F12: 45979 | G12: 46006 | H12: 46006 | I12: 22348522507332
A13: 22147523023858 | B13: Finger Scanner (RS5100) | C13: Will not power on. | D13: B480353-200621304 | E13: 46001 | F13: 46021 | G13: 46041 | H13: 46041 | I13: 22147523023858
A14: 22332522507151 | B14: Hand Held (TC58) | C14: Both side scan buttons are not working. | D14: B480304-200620769 | E14: 46001 | F14: 46002 | G14: 46017 | H14: 46017 | I14: 22332522507151
A15: 22348522505268 | B15: Hand Held (TC58) | C15: Will not power on. | D15: B478368-200572634 | E15: 45976 | F15: 45976 | G15: 46006 | H15: 46006 | I15: 22348522505268
A16: 22333522509979 | B16: Hand Held (TC58) | C16: Right side scan buttons is not working. | D16: B480989-200636493 | E16: 46006 | F16: 46007 | G16: 45683 | H16: 46034 | I16: 22333522509979
A17: 22323522509986 | B17: Hand Held (TC58) | C17: Will not power on. | D17: B480991-200636502 | E17: 46006 | F17: 46007 | G17: 46035 | H17: 46034 | I17: 22323522509986
A18: 22322522503014 | B18: Hand Held (TC58) | C18: Stuck on Smart Ops and no WIFI. | D18: B483442-200689305 | E18: 46027 | F18: 46028 | G18: 46044 | H18: 46044 | I18: 22322522503014
A19: 22325522505119 | B19: Hand Held (TC58) | C19: Stuck on a white screen and no WIFI. | D19: B483444-200689313 | E19: 46027 | F19: 46028 | G19: 46044 | H19: 46044 | I19: 22325522505119
A20: 22332522506035 | B20: Hand Held (TC58) | C20: Stuck on a white screen and no WIFI. | D20: B483443-200689311 | E20: 46027 | F20: 46028 | G20: 46044 | H20: 46044 | I20: 22332522506035
A21: 22325522504983 | B21: Hand Held (TC58) | C21: Right scanning button is not working. | D21: B485307-200730121 | E21: Friday, January 16, 2026 | F21: Friday, January 16, 2026 | G21: 46058 | H21: 46058 | I21: 22325522504983
A22: 22349522504478 | B22: Hand Held (TC58) | C22: Right scanning button is not working. | D22: B485308-200730125 | E22: Friday, January 16, 2026 | F22: Friday, January 16, 2026 | G22: 46058 | H22: 46058 | I22: 22349522504478
A23: 22348522505015 | B23: Hand Held (TC58) | C23: Right scanning button is not working. | D23: B485309-200730130 | E23: Friday, January 16, 2026 | F23: Friday, January 16, 2026 | G23: 46058 | H23: 46058 | I23: 22348522505015
A24: 22333522510206 | B24: Hand Held (TC58) | C24: Right scanner button is not working & Bluetooth app will not open. | D24: B482797-200675280 | E24: 46021 | F24: 46021 | G24: 46044 | H24: 46044 | I24: 22333522510206
A25: S22348522507362 | B25: Hand Held (TC58) | C25: Right scanner button is not working. | D25: B488335-200792652 | E25: 46059 | F25: 46059

Sheet YOY Comparison
A1: YEAR-OVER-YEAR COMPARISON
A4: Device Type | B4: Prior Total | C4: Prior Good | D4: Prior Bad | E4: Current Total | F4: Curr Good | G4: Curr Bad | H4: Curr Lost | I4: Variance | J4: Trend
A5: TC58 | B5: 118 | C5: 110 | D5: 8 | J5: =IF(I5>0,"▲",IF(I5<0,"▼","—")) -> —
A6: ET45 | B6: 73 | C6: 73 | D6: 0 | J6: =IF(I6>0,"▲",IF(I6<0,"▼","—")) -> —
A7: ET56 | B7: 73 | C7: 72 | D7: 1 | J7: =IF(I7>0,"▲",IF(I7<0,"▼","—")) -> —
A8: L10WA | B8: 60 | C8: 59 | D8: 1 | J8: =IF(I8>0,"▲",IF(I8<0,"▼","—")) -> —
A9: MC930 | B9: 26 | C9: 25 | D9: 1 | J9: =IF(I9>0,"▲",IF(I9<0,"▼","—")) -> —
A10: TC57 | B10: 39 | C10: 39 | D10: 0 | J10: =IF(I10>0,"▲",IF(I10<0,"▼","—")) -> —
A11: DS3608 | B11: 46 | C11: 46 | D11: 0 | J11: =IF(I11>0,"▲",IF(I11<0,"▼","—")) -> —
A12: RS5100 | B12: 120 | C12: 116 | D12: 4 | J12: =IF(I12>0,"▲",IF(I12<0,"▼","—")) -> —
A13: RelayX | B13: 104 | C13: 104 | D13: 0 | J13: =IF(I13>0,"▲",IF(I13<0,"▼","—")) -> —
A14: QP148454 | B14: 7 | C14: 7 | D14: 0 | J14: =IF(I14>0,"▲",IF(I14<0,"▼","—")) -> —
A15: TC58 Accessory | B15: 36 | C15: 35 | D15: 1 | J15: =IF(I15>0,"▲",IF(I15<0,"▼","—")) -> —
A16: TC58 Battery | B16: 167 | C16: 164 | D16: 3 | J16: =IF(I16>0,"▲",IF(I16<0,"▼","—")) -> —
... A20: VoCollect | B20: 39 | C20: 39 | D20: 0 | J20: =IF(I20>0,"▲",IF(I20<0,"▼","—")) -> —

Sheet MOM Comparison
A1: MONTH-OVER-MONTH COMPARISON
A4: Month | B4: TC58 | C4: TC57 | D4: ET56 | E4: ET45 | F4: L10WA | G4: MC930 | H4: RS5100 | I4: DS3608 | J4: TC58 Battery | K4: TC57 Battery | L4: MC930 Battery | M4: Total
A5: December | B5: 118 | C5: 0 | D5: 72 | E5: 74 | F5: 61 | G5: 26 | H5: 120 | I5: 46 | J5: 167 | K5: 0 | L5: 19 | M5: =SUM(Table8[[#This Row],[TC58]:[MC930 Battery]]) -> 703
A6: January | B6: 118 | C6: 0 | D6: 72 | E6: 75 | F6: 60 | G6: 25 | H6: 118 | I6: 46 | J6: 167 | K6: 0 | L6: 19 | M6: =SUM(Table8[[#This Row],[TC58]:[MC930 Battery]]) -> 700
A7: February | M7: =SUM(Table8[[#This Row],[TC58]:[MC930 Battery]]) -> 0
A8: March | M8: =SUM(Table8[[#This Row],[TC58]:[MC930 Battery]]) -> 0
A9: April | M9: =SUM(Table8[[#This Row],[TC58]:[MC930 Battery]]) -> 0
A10: May | M10: =SUM(Table8[[#This Row],[TC58]:[MC930 Battery]]) -> 0
A11: June | M11: =SUM(Table8[[#This Row],[TC58]:[MC930 Battery]]) -> 0
A12: July | M12: =SUM(Table8[[#This Row],[TC58]:[MC930 Battery]]) -> 0
A13: August | M13: =SUM(Table8[[#This Row],[TC58]:[MC930 Battery]]) -> 0
A14: September | M14: =SUM(Table8[[#This Row],[TC58]:[MC930 Battery]]) -> 0
A15: October | M15: =SUM(Table8[[#This Row],[TC58]:[MC930 Battery]]) -> 0
A16: November | M16: =SUM(Table8[[#This Row],[TC58]:[MC930 Battery]]) -> 0
A17: December | M17: =SUM(Table8[[#This Row],[TC58]:[MC930 Battery]]) -> 0

Sheet Dropdown Lists
A1: Condition | B1: Status | C1: Model | D1: Location/Zone | E1: Shift | F1: Handedness | G1: Site Code
A2: Good | B2: In Field | C2: Hand Held (TC58) | D2: Pick Module A | E2: 1st | F2: Left | G2: PLCB
A3: Bad | B3: Shipped | C3: Hand Held (TC57) | D3: Pick Module B | E3: 2nd | F3: Right | G3: NHLC
A4: RMA | B4: Damaged | C4: Tablet (ET56) | D4: Pick Module C | E4: 3rd | F4: Both | G4: Jobs
A5: Lost | B5: System Office | C5: Tablet (ET45) | D5: Receiving Dock | E5: Flex | F5: N/A
B6: Training | C6: MHE Tablet (L10) | D6: Shipping Dock | E6: All Shifts
B7: Operation | C7: Brick Scanner (MC930) | D7: Staging Area
B8: Transportation | C8: Finger Scanner (RS5100) | D8: QC Station
B9: Inventory | C9: DS3608 (Green Scanner) | D9: Returns Processing
B10: Safety | C10: Walkie (NX-1300) | D10: Inventory Control
B11: Spare | C11: RY2268 (Walkie) | D11: MHE Charging
B12: Server Room | C12: TC58 Battery | D12: System Office
B13: Lost | C13: TC57 Battery | D13: Training Room
B14: RMA Pending | C14: MC930 Battery | D14: Server Room
B15: Decommissioned | C15: RS5100 Battery | D15: Maintenance
C16: TC58 Accessory
C17: Quick Pick (148454)
C18: RelayX (radio)
C19: VoCollect
C20: Honeywell (RT10)
C21: HP Laptops

Sheet Instructions
A1: ASSET AUDIT TEMPLATE - QUICK START GUIDE
A4: WORKFLOW
A5: 1. Setup | B5: Fill in Site Code, Site Name, and Auditor on Executive Summary
A6: 2. Load Assets | B6: Import or enter all known assets into Asset Detail sheet
A7: 3. Physical Audit | B7: Use Scan Audit sheet - scan each device's barcode
A8: 4. Review Matches | B8: Check Match Status column for Found vs Not Found
A9: 5. Investigate | B9: Use Missing Report to track down unscanned assets
A10: 6. Finalize | B10: Review Executive Summary KPIs before submitting
A12: CONDITION CODES
A13: Good | B13: Asset functioning properly
A14: Bad | B14: Asset has issues, may be repairable on-site
A15: RMA | B15: Requires return to vendor
A16: Lost | B16: Cannot be located
A18: SCAN AUDIT TIPS
A19: • Scan barcodes | B19: Asset Number field auto-matches to inventory
A20: • Check marks | B20: ✓ Found = in system | ✗ Not Found = unknown asset
A21: • Progress % | B21: Shows audit completion rate
A23: COST REFERENCE
A24: TC58 Handheld
A25: TC57 Handheld
A26: L10 MHE Tablet
A27: MC930 Scanner
A28: RS5100 Scanner
A29: Batteries
